<?xml version="1.0"?>
<robot name="LD_Platform">
  <material name="blue">
    <color rgba="0 0 0.8 1"/>
  </material>
  <material name="black">
    <color rgba="0 0 0 1"/>
  </material>
  <material name="white">
    <color rgba="1 1 1 1"/>
  </material>

  <link name="base_link">
  </link>

  <link name="main_body">
    <visual>
      <origin xyz="0 0 0" rpy="1.5707963267949 0 1.5707963267949" />
      <geometry>
        <mesh filename="package://ld_urdf/meshes/LD_Platform.STL" />
      </geometry>
      <origin rpy="0 0 0" xyz="0 0 0.17"/>
      <material name="white"/>
    </visual>
    <collision>
      <origin xyz="0 0 0" rpy="1.5707963267949 0 1.5707963267949" />
      <geometry>
        <mesh filename="package://ld_urdf/meshes/LD_Platform.STL" />
      </geometry>
    </collision>
    <inertial>
      <mass value="4.07"/>
      <inertia ixx="0.426" ixy="0.0" ixz="0.0" iyy="0.496" iyz="0.0" izz="0.91"/>
    </inertial>
  </link>

  <joint name="main_body_to_base" type="fixed">
    <parent link="base_link"/>
    <child link="main_body"/>
    <origin xyz="0 0 0.085"/>
  </joint>

  <link name="left_wheel">
    <visual>
      <origin rpy="1.57075 0 0" xyz="0 0 0"/>
      <geometry>
        <cylinder length="0.03937" radius="0.088"/>
      </geometry>
      <material name="black"/>
    </visual>
    <collision>
      <geometry>
        <cylinder length="0.03937" radius="0.088"/>
      </geometry>
    </collision>
    <inertial>
      <mass value="0.17"/>
      <inertia ixx="0.000204" ixy="0.0" ixz="0.0" iyy="0.000306" iyz="0.0" izz="0.000204"/>
    </inertial>
  </link>

  <joint name="left_wheel_joint" type="continuous">
    <axis rpy="0 0 0" xyz="0 1 0"/>
    <parent link="main_body"/>
    <child link="left_wheel"/>
    <origin rpy="0 0 0" xyz="0.0 0.196425 0.000881"/>
  </joint> 

  <link name="right_wheel">
    <visual>
      <origin rpy="1.57075 0 0" xyz="0 0 0"/>
      <geometry>
        <cylinder length="0.03937" radius="0.088"/>
      </geometry>
      <material name="black"/>
    </visual>
    <collision>
      <geometry>
        <cylinder length="0.03937" radius="0.088"/>
      </geometry>
    </collision>
    <inertial>
      <mass value="0.17"/>
      <inertia ixx="0.000204" ixy="0.0" ixz="0.0" iyy="0.000306" iyz="0.0" izz="0.000204"/>
    </inertial>
  </link>

  <joint name="right_wheel_joint" type="continuous">
    <axis rpy="0 0 0" xyz="0 1 0"/>
    <parent link="main_body"/>
    <child link="right_wheel"/>
    <origin rpy="3.1416 0 0" xyz="0.0 -0.196425 0.000881"/>
  </joint>

  <link name="right_front_small_wheel">
    <visual>
      <origin rpy="1.57075 0 0" xyz="0 0 0"/>
      <geometry>
        <cylinder length="0.02775" radius="0.0375"/>
      </geometry>
      <material name="black"/>
    </visual>
    <collision>
      <geometry>
        <cylinder length="0.02775" radius="0.0375"/>
      </geometry>
    </collision>
    <inertial>
      <mass value="0.17"/>
      <inertia ixx="0.000204" ixy="0.0" ixz="0.0" iyy="0.000306" iyz="0.0" izz="0.000204"/>
    </inertial>
  </link>

  <joint name="right_front_small_wheel_joint" type="continuous">
    <axis rpy="0 0 0" xyz="0 1 0"/>
    <parent link="main_body"/>
    <child link="right_front_small_wheel"/>
    <origin rpy="3.1416 0 0" xyz="0.209 -0.108 -0.049"/>
  </joint>

  <link name="left_front_small_wheel">
    <visual>
      <origin rpy="1.57075 0 0" xyz="0 0 0"/>
      <geometry>
        <cylinder length="0.02775" radius="0.0375"/>
      </geometry>
      <material name="black"/>
    </visual>
    <collision>
      <geometry>
        <cylinder length="0.02775" radius="0.0375"/>
      </geometry>
    </collision>
    <inertial>
      <mass value="0.17"/>
      <inertia ixx="0.000204" ixy="0.0" ixz="0.0" iyy="0.000306" iyz="0.0" izz="0.000204"/>
    </inertial>
  </link>

  <joint name="left_front_small_wheel_joint" type="continuous">
    <axis rpy="0 0 0" xyz="0 1 0"/>
    <parent link="main_body"/>
    <child link="left_front_small_wheel"/>
    <origin rpy="0 0 0" xyz="0.209 0.108 -0.049"/>
  </joint> 

  <link name="left_back_small_wheel">
    <visual>
      <origin rpy="1.57075 0 0" xyz="0 0 0"/>
      <geometry>
        <cylinder length="0.02775" radius="0.0375"/>
      </geometry>
      <material name="black"/>
    </visual>
    <collision>
      <geometry>
        <cylinder length="0.02775" radius="0.0375"/>
      </geometry>
    </collision>
    <inertial>
      <mass value="0.17"/>
      <inertia ixx="0.000204" ixy="0.0" ixz="0.0" iyy="0.000306" iyz="0.0" izz="0.000204"/>
    </inertial>
  </link>

  <joint name="left_back_small_wheel_joint" type="continuous">
    <axis rpy="0 0 0" xyz="0 1 0"/>
    <parent link="main_body"/>
    <child link="left_back_small_wheel"/>
    <origin rpy="0 0 0" xyz="-0.228 0.156 -0.049"/>
  </joint>
  
  <link name="right_back_small_wheel">
    <visual>
      <origin rpy="1.57075 0 0" xyz="0 0 0"/>
      <geometry>
        <cylinder length="0.02775" radius="0.0375"/>
      </geometry>
      <material name="black"/>
    </visual>
    <collision>
      <geometry>
        <cylinder length="0.02775" radius="0.0375"/>
      </geometry>
    </collision>
    <inertial>
      <mass value="0.17"/>
      <inertia ixx="0.000204" ixy="0.0" ixz="0.0" iyy="0.000306" iyz="0.0" izz="0.000204"/>
    </inertial>
  </link>

  <joint name="right_back_small_wheel_joint" type="continuous">
    <axis rpy="0 0 0" xyz="0 1 0"/>
    <parent link="main_body"/>
    <child link="right_back_small_wheel"/>
    <origin rpy="3.1416 0 0" xyz="-0.228 -0.156 -0.049"/>
  </joint>
</robot>
